Workbook

Sheet Gold Set
A1: # | B1: Week | C1: Difficulty | D1: Topic | E1: Question | F1: Must Include (key concepts) | G1: Prereq Should Fire? | H1: System Answer (paste) | I1: M1: Correctness (1-5) | J1: M2: Faithfulness (1-5) | K1: M3: Answer Relevance (1-5) | L1: M4: Context Relevance (1-5) | M1: M5: Latency (s) | N1: Confidence Band | O1: Prereq Fired? (Y/N) | P1: Notes / Failure mode | Q1: Retrieved Context (chunks) | R1: Signal 1 (band | mean dist) | S1: Signal 2 (verify 1-3)
A2: 1 | B2: Week 1 | C2: Easy | D2: CIA Triad | E2: What does the CIA triad stand for in network security? | F2: Confidentiality, Integrity, Availability | G2: No | H2: The CIA triad is a shorthand for the three core security properties that most network‑level security mechanisms aim to protect: - **C**onfidentiality – ensuring that data are not disclosed to unauthorized parties. - **I**ntegrity – ensuring that data are not altered or corrupted without authorization. - **A**vailability – ensuring that legitimate users can access resources and services when needed. These three principles are the basis for defining security policies and selecting appropriate mechanisms such as encryption, authentication, and traffic‑shaping controls in network security. | I2: 5 | J2: 4 | K2: 5 | L2: 3 | M2: 1.16 | N2: Low | O2: N | Q2: [Source 1 | Week 1 | Network attacks | lecture | dist=0.971] communication between two entities, resembling an aeroplane hijacker taking control of a flight. For instance, a session hijacking attack involves an attacker intercepting packets between two components and taking control of the session between them by inserting their own packet. Poisoning We refer to poisoning as a way to contaminate some source of information that we usually believe is good. Later on in the module, we are going to learn more about ARP poisoning and DNS cache poisoning. Each type of attack can be linked to one of the security principles (see ‘CIA triad’ in lesson ‘How do we define security?’). [Graphic – full-width] Redraw Figure: CIA triad: confidentiality, integrity, availability. Read text below on how different attacks are linked to each assurance. Caption: Sniffing attacks the confidentiality of the communication, since it corresponds to theft or interception of data by capturing network traffic. A potential solution for sniffing is using cryptography to encrypt the communication. Spoofing and poisoning attack the integrity. The goal of a poisoning attack is to change something by corrupting or manipulating information. A spoofing attack also attacks integrity, since it allows the attacker to pretend to be someone else. In order to protect integrity, we can leverage keys to sign what we want to protect. In case of alteration, we would be able to discover that our data were tampered with. A jamming attack compromises the availability of the communication channel, creating noise to make the communication impossible. Policies are a measure to help protect against jamming attacks, restricting what the users can do in the communication channels. Of course, the above solutions are not always feasible and often we need to balance practicality and cost with the importance of the data we want to protect. Off-path vs on-path attackers Finally, let’s look at a useful distinction between two different types of attack: on-path and off-path. On-path means the attacker is operating within the same network. Off-path means they are attacking from outside the network. On-path attacks are much more powerful as it is very difficult to insert false data off-path. There was a lot of terminology introduced in these opening lessons. Take your time to review the definitions as they are used throughout the module. Reference We have used the following sources to compile this lesson. You do not need to read these; they are simply there for your reference and in case you would like to learn more about the information presented in this lesson. [1] J. Postel, “Internet Protocol – DARPA Internet Program Protocol Specification,” Defense Advanced Research Projects Agency, Arlington, Virginia, RFC 791, 1981. [Online]. Available: https://datatracker.ietf.org/doc/html/rfc791 [Source 2 | Week 1 | How do we define security | lecture | dist=1.059] 1.5 How do we define security? As a security expert responsible for security design, it is necessary to understand three things: Who or what is being protected? Who or what is attacking? What are the attacker’s powers? The answers to these questions make up what is called the threat model. Before starting to talk about securing a network, it is necessary to work out what the potential threats are for that specific network. As part of any analysis, we have principals. These principals are actors and participants that have a role in our analysis. Some agents are honest and some are not. As in many examples, let’s consider Alice and Bob. [Graphic – full-width] Figure: A diagram showing Alice and Bob communicating over a network, with a dishonest agent, Mallory, intercepting their communications. Caption: Alice and Bob use the internet to exchange information. Alice and Bob are the honest agents. However, the internet is vast and the communication between Alice and Bob is of some kind of interest for Mallory, who is a dishonest agent. Mallory is exploiting some internet vulnerabilities to get access to the information exchanged by Alice and Bob. How to define security Once we have identified the principals that can affect the security, we need to understand what security means. [Key concept box] Security can be defined as a combination of policy and mechanism. Policy and security properties A security policy is just a statement about what is allowed and not allowed to do in a system or on the ‘object’ being protected. This is defined by specifying security properties that must hold. The most common security properties are confidentiality, integrity and availability, which constitute what is commonly known as the CIA triad. [Card vertical (no image)] Confidentiality Assures that private or confidential information is not disclosed to unauthorised individuals. [Card vertical (no image)] Integrity Assures that information and programs are changed only in a specified and authorised manner. [Card vertical (no image)] Availability Assures that systems work promptly and service is not denied to authorised users. Security mechanisms Once we have the security properties, we need security mechanisms which describe how to implement the security properties. We can think of the mechanisms as tools, methodologies or procedures for security enforcement. For example, let’s say to protect the integrity of the network we have introduced the security mechanisms ‘Only "root" can execute this script’. We can then enforce this property by asking users to input the admin password in addition to checking if the user ID has root privileges. A different example of a property is that voters can only vote once in any given election. This is then implemented in many countries by the mechanism of staining the voters’ fingers with indelible ink to detect if they return back. In other countries the name of the voter is deleted from a database. We can refer to security mechanisms based on their type. The following three are the most important. [Card vertical (no image)] Deter Deterring [Source 3 | Week 1 | Knowledge check PDF | quiz | dist=1.107] ___________ is how individuals and organisation reduce the risk of network attack. a.Network security b.Data security c. Cyber security d.Systems security e.Information security Your answer is incorrect. The correct answer is: Network security ___________ involves the passive capture of a data unit and its subsequent transmission to produce an unauthorised eﬀect. a.Man-in-the-middle attack b.Denial of service attack c. Masquerade d.Replay attack e.Disruption Your answer is incorrect. The correct answer is: Replay attack ____________ is a security mechanism that inserts bits into gaps in a data stream to frustrate traﬃc analysis. a.Access control b.Security recovery c. Notarisation d.Traﬃc padding e. Compression Your answer is incorrect. The correct answer is: Traﬃc padding All the techniques for providing security have two components: a security-related transformation on the information to be sent and some secret information shared by the two principals. Select one: True False The correct answer is 'True'. Which one of the security properties in the CIA triad is the most important? a.Conﬁdentiality b.Availability c. They are equally important d.The importance is situational e.Integrity Your answer is incorrect. The correct answer is: The importance is situational Which service is the one that protects a system to ensure its availability and addresses the security concerns raised by denial- of- service attacks? a.replay b.masquerade c. integrity d.non-repudiation e.availability Your answer is incorrect. The correct answer is: availability The ﬁrst step in the 5Ds of perimeter security is ____________. a.defend b.detect c. delay d.deter e.deny Your answer is incorrect. The correct answer is: deter Listening to network conversation that are not intended for you is called ___________. a.jamming b.sniﬃng c. spooﬁng d.ﬂooding e. hijacking Your answer is incorrect. The correct answer is: sniﬃng A _____________ is any action that compromises the security of information owned by an organisation. a.security monitoring b.security service c. security attack d.security alert e.security mechanism Your answer is incorrect. The correct answer is: security attack ________________ is an attack that pretends to be somebody you are not. a.jamming b.sniﬃng c. ﬂooding d.spooﬁng e.smurﬁng Your answer is incorrect. The correct answer is: spooﬁng  [Source 4 | Week 5 | Quiz week 1-5 | quiz | dist=1.194] text: Which attack is considered as an active attack? Settings Number of answers: [One/Multiple] Shuffle answers? [Yes/No] Answers (Please highlight the correct answer) Feedback (Optional feedback for each individual answer) Sniffing This is incorrect. Port mirroring This is incorrect. Network tapping This is incorrect. Spoofing This is correct. Eavesdropping This is incorrect. General Feedback Sniffing, network tapping, port mirroring and eavesdropping are passive attacks. Only spoofing is an active attack. [new page] Alice and Bob are CEO and CFO of a cooperation called SecureGalaxia, and you are a network administrator. Alice and Bob used to share a big open office with other colleagues including Charly and David before the Covid –19 pandemic. The simplified topology of their local area network is shown below, with the IP address of their machines listed. [Graphic – full-width] Figure: View the description below. Caption: [View description] View description In the local area network, four machines are connected to one central server. Their IP addresses are listed as below. Bob’s IP address: 10.0.0.2 David’s IP address: 10.0.0.5 Charly’s IP address: 10.0.0.4 Alice’s IP address: 10.0.0.3 One day you wanted to install an update on Bob’s machine. When you checked the ARP table on his machine, you saw the output as below: (10.0.0.2) at 1e:25:d2:11:8c:a2 [either] on h1-eth0 (10.0.0.4) at cc:cc:cc:cc:cc:cc [either] PERM on h1-eth0 (10.0.0.3) at cc:cc:cc:cc:cc:cc [either] PERM on h1-eth0 You thought this is strange, knowing that the MAC address cc:cc:cc:cc:cc:cc is Charly’s machine. However, Bob never had any problems of communicating with Alice on the network. [Essay question] Question Question number: Question text: What do you think is happening? In your analysis, include the following: What type of attack is this? What does the ARP table on Alice’s machine look like when she checks? Describe the attack in full detail in the context of the given scenario. What can Alice and Bob do to mitigate such attack(s) in the future? General feedback (relevant for the question as a whole) What type of attack is this? What does the ARP table at Alice’s machine look like when she checks? To answer this question, you are advised to revisit the week 3 lessons on network attacks, ARP spoofing, ARP poisoning and ARP cache poisoning. This is an ARP spoofing/ARP poisoning/ARP cache poisoning/man-in-the-middle attack. The ARP table shown on Alice’s machine looks like this: (10.0.0.3) at xx:xx:xx:xx:xx:xx [ether] on eth0, where xx:xx:xx:xx:xx:xx can be any valid Ethernet MAC address. x should be between 0 to f. eth0 can be any other port number except localhost. (10.0.0.4) at cc:cc:cc:cc:cc:cc [ether] PERM on h1-eth0. The fields from PERM are for examples only. (10.0.0.2) at cc:cc:cc:cc:cc:cc [ether] PERM on h1-etho. The fields from PERM are for examples only. Describe the attack in full detail with the given scenario. Your answer should describe how Charly mounts the attack, spoofs the ARP response and poisons the ARP cache, for both Alice and Bob, and becomes the man-in-the-middle of the communication between Alice and Bob. You may use diagram(s) to illustrate the [Source 5 | Week 5 | Firewall topologies | lecture | dist=1.221] a relatively insecure network and make use of encryption and special protocols to provide security. They use encryption and authentication in the lower protocol layers to provide a secure connection through an otherwise insecure network, typically the internet. Encryption may be performed by firewall software or by routers. The most common protocol mechanism used for this purpose is at the IP level and is known as IPsec. [Graphic – full-width] Figure: A diagram showing computers connecting on a network using IPSec; see description for details. Caption: [View description] View description A user system with IPSec sends information over a public and private network. The information contains an IP header, IPSec header and a secure IP payload. The information is sent to two systems, both with firewalls with IPSec. The IPSec header is removed from the information sent and it continues to Ethernet switches which distribute the information to computers and servers. Distributed firewalls A distributed firewall configuration involves stand-alone firewall devices and host-based firewalls working together under a central administrative control. Admins can configure the host-resident firewalls on hundreds of servers and workstations, as well as personal firewalls on local and remote user systems. These firewalls protect against internal attacks and provide protection tailored to specific machines and applications. [Graphic – full-width] Figure: A diagram showing a complex network configuration with multiple firewalls; see description for details. Caption: [View description] View description The diagram shows a remote user connecting to the network through the internet. The connection from the internet starts with a boundary router, which firstly splits traffic into an external DMZ network containing the web servers. The connection from the boundary router also continues to an external firewall and the first LAN switch. The first LAN switch splits into an internal DMZ network containing more web servers, an email server and a DNS server. The first LAN switch also continues through an internal firewall to a second LAN switch which connects to the internal protected network containing application and database servers, and workstations. All devices on the network also have individual host-resident firewalls. With distributed firewalls, it makes sense to have both an internal and an external DMZ. Web servers, which typically have less critical information on them and therefore need less protection, are placed in an external DMZ, outside the external firewall. Their protection is provided by host-based firewalls. An important aspect of this configuration is security monitoring which includes log aggregation and analysis, firewall statistics and fine-grained remote monitoring of individual hosts. [Card vertical (no image)] Host-resident firewall Includes personal firewall software and firewall software on servers. Can be used alone or as part of an in-depth firewall deployment. [Card vertical (no image)] Screening router A single router between internal and external networks with stateless or full packet filtering. Typical for small office/home office applications. [Card vertical (no image)] Single bastion inline A single firewall device between an internal and external router. Firewall may implement stateful filters and/or application proxies. Typical configuration for small to medium-sized | R2: Low | 1.111 | S2: 3
A3: 2 | B3: Week 1 | C3: Easy | D3: Security services | E3: What does authentication mean in network security? | F3: Verifying identity of a user or system before granting access | G3: No | H3: Authentication in network security is the process of verifying the identity of a user, device, or process before granting access to network resources or allowing network traffic to pass through security controls. It ensures that only legitimate, recognised entities can initiate or receive communications, and forms the basis for enforcing security policies such as user‑control in firewalls or the secure authentication required for IPsec VPNs. **Sources**: Week 5 – *Firewall topologies* and *What is a firewall* (mention of authentication in IPsec and user control). | I3: 5 | J3: 2 | K3: 5 | L3: 2 | M3: 0.67 | N3: Low | O3: N | Q3: [Source 1 | Week 5 | Firewall topologies | lecture | dist=0.964] a relatively insecure network and make use of encryption and special protocols to provide security. They use encryption and authentication in the lower protocol layers to provide a secure connection through an otherwise insecure network, typically the internet. Encryption may be performed by firewall software or by routers. The most common protocol mechanism used for this purpose is at the IP level and is known as IPsec. [Graphic – full-width] Figure: A diagram showing computers connecting on a network using IPSec; see description for details. Caption: [View description] View description A user system with IPSec sends information over a public and private network. The information contains an IP header, IPSec header and a secure IP payload. The information is sent to two systems, both with firewalls with IPSec. The IPSec header is removed from the information sent and it continues to Ethernet switches which distribute the information to computers and servers. Distributed firewalls A distributed firewall configuration involves stand-alone firewall devices and host-based firewalls working together under a central administrative control. Admins can configure the host-resident firewalls on hundreds of servers and workstations, as well as personal firewalls on local and remote user systems. These firewalls protect against internal attacks and provide protection tailored to specific machines and applications. [Graphic – full-width] Figure: A diagram showing a complex network configuration with multiple firewalls; see description for details. Caption: [View description] View description The diagram shows a remote user connecting to the network through the internet. The connection from the internet starts with a boundary router, which firstly splits traffic into an external DMZ network containing the web servers. The connection from the boundary router also continues to an external firewall and the first LAN switch. The first LAN switch splits into an internal DMZ network containing more web servers, an email server and a DNS server. The first LAN switch also continues through an internal firewall to a second LAN switch which connects to the internal protected network containing application and database servers, and workstations. All devices on the network also have individual host-resident firewalls. With distributed firewalls, it makes sense to have both an internal and an external DMZ. Web servers, which typically have less critical information on them and therefore need less protection, are placed in an external DMZ, outside the external firewall. Their protection is provided by host-based firewalls. An important aspect of this configuration is security monitoring which includes log aggregation and analysis, firewall statistics and fine-grained remote monitoring of individual hosts. [Card vertical (no image)] Host-resident firewall Includes personal firewall software and firewall software on servers. Can be used alone or as part of an in-depth firewall deployment. [Card vertical (no image)] Screening router A single router between internal and external networks with stateless or full packet filtering. Typical for small office/home office applications. [Card vertical (no image)] Single bastion inline A single firewall device between an internal and external router. Firewall may implement stateful filters and/or application proxies. Typical configuration for small to medium-sized [Source 2 | Week 1 | How do we define security | lecture | dist=1.105] 1.5 How do we define security? As a security expert responsible for security design, it is necessary to understand three things: Who or what is being protected? Who or what is attacking? What are the attacker’s powers? The answers to these questions make up what is called the threat model. Before starting to talk about securing a network, it is necessary to work out what the potential threats are for that specific network. As part of any analysis, we have principals. These principals are actors and participants that have a role in our analysis. Some agents are honest and some are not. As in many examples, let’s consider Alice and Bob. [Graphic – full-width] Figure: A diagram showing Alice and Bob communicating over a network, with a dishonest agent, Mallory, intercepting their communications. Caption: Alice and Bob use the internet to exchange information. Alice and Bob are the honest agents. However, the internet is vast and the communication between Alice and Bob is of some kind of interest for Mallory, who is a dishonest agent. Mallory is exploiting some internet vulnerabilities to get access to the information exchanged by Alice and Bob. How to define security Once we have identified the principals that can affect the security, we need to understand what security means. [Key concept box] Security can be defined as a combination of policy and mechanism. Policy and security properties A security policy is just a statement about what is allowed and not allowed to do in a system or on the ‘object’ being protected. This is defined by specifying security properties that must hold. The most common security properties are confidentiality, integrity and availability, which constitute what is commonly known as the CIA triad. [Card vertical (no image)] Confidentiality Assures that private or confidential information is not disclosed to unauthorised individuals. [Card vertical (no image)] Integrity Assures that information and programs are changed only in a specified and authorised manner. [Card vertical (no image)] Availability Assures that systems work promptly and service is not denied to authorised users. Security mechanisms Once we have the security properties, we need security mechanisms which describe how to implement the security properties. We can think of the mechanisms as tools, methodologies or procedures for security enforcement. For example, let’s say to protect the integrity of the network we have introduced the security mechanisms ‘Only "root" can execute this script’. We can then enforce this property by asking users to input the admin password in addition to checking if the user ID has root privileges. A different example of a property is that voters can only vote once in any given election. This is then implemented in many countries by the mechanism of staining the voters’ fingers with indelible ink to detect if they return back. In other countries the name of the voter is deleted from a database. We can refer to security mechanisms based on their type. The following three are the most important. [Card vertical (no image)] Deter Deterring [Source 3 | Week 1 | Overview and learning outcomes | overview | dist=1.126] 1.1 Overview and learning outcomes Welcome to week 1 of this module on Network Security. On successful completion of this week, you will understand how a network is structured, gaining an idea of how security properties are linked to the general categories of attacks that affect a network infrastructure. [Learning outcome box] Learning outcomes By the end of this week, you should be able to: Describe basic security terminology and how security inside a network is achieved. Describe the OSI model and show knowledge of each of the network layers. Describe the different kind of attacks, relating them with the basic security properties. [Source 4 | Week 5 | What is a firewall | lecture | dist=1.174] 5.3 What is a firewall? Nowadays, everyone wants to be connected to the internet. However, as we saw in the previous week, being connected to the internet might expose us to cyberattacks. So, what security measures do we have at our disposal? One of the main security systems we have is called a firewall. [Definition box] Firewall A computer or a network security system that sits between one’s internal network and an external network such as the internet. It attempts to prevent unwanted or malicious traffic – such as internal users sending company secrets out of the network, or outsiders breaking into the system – without preventing legitimate traffic, such as employees accessing information available externally. [Graphic – full-width] Figure: A diagram showing several computers connected on a LAN, which are connected to WAN through a firewall. Caption: A typical use of a firewall is to provide a perimeter defence with a single choke point. But, as we are going to see, there might be more ways to take advantage of a firewall. A firewall is just one piece of a comprehensive security strategy. Generally, firewalls can be used to protect a network, but they can also be used to feed alerts to advanced Intrusion Detection Systems (IDS) and to implement Intrusion Prevention Systems (IPS), as we are going to see later on. To put it differently, a firewall forms a barrier through which all the traffic going in each direction must pass. A firewall security policy dictates which traffic is authorised to pass in each direction. You can also think of a firewall as a choke point for control and monitoring. It may be designed to operate as a filter at the level of IP packets, or may operate at a higher protocol layer. It interconnects networks with differing trust levels and imposes restrictions on network services such that only authorised traffic is allowed through. Whilst auditing and controlling access, it can implement alarms for abnormal behaviour. It’s also a convenient platform for several internet functions that are not security-related, such as NAT and internet usage audits or logs, and implements VPNs using IPSec. Above all else, it must be immune to penetration. Firewalls provide an additional layer of defence, insulating the internal systems from external networks. Originally, firewalls focused primarily on service control, but they have since evolved, and there are four primary techniques used by firewalls to control access and enforce security policy. [Card vertical (no image)] Service control This control determines the types of internet services that can be accessed, inbound or outbound. Firewall may filter traffic on the basis of IP address, protocol or TCP port number used. For example, incoming HTTP requests can be rejected unless they are directed to an official web server host. [Card vertical (no image)] Direction control This control regulates the direction in which particular service requests may be initiated and allowed to flow through the firewall. [Card vertical (no image)] User control A user control manages or authorises admission [Source 5 | Week 5 | What is a firewall | lecture | dist=1.18] rejected unless they are directed to an official web server host. [Card vertical (no image)] Direction control This control regulates the direction in which particular service requests may be initiated and allowed to flow through the firewall. [Card vertical (no image)] User control A user control manages or authorises admission to a service according to which entity is trying to access that specified service. This feature is applied to users inside the firewall perimeter (internal users). It may also be applied to incoming traffic from external users. It requires some form of secure authentication technology. Using Ipsec and similar protocols, this feature can be applied to incoming traffic from external users. [Card vertical (no image)] Behaviour control This controls how particular services are used. It keeps track of particular services in order to find any malicious activity in the service. An example would be blocking spam mails by filtering addresses. Firewall limitations A firewall cannot protect from attacks that bypass it or against malware imported via a laptop, a PDA, or storage that was infected from outside the network. For example: sneakernet, utility modems, trusted organisations, trusted services (eg SSL/SSH), etc. [Definition box] Sneakernet An informal term describing the transfer of electronic information, especially computer files, by physically moving removable media such as magnetic tape, floppy disks, compact discs, USB flash drives (thumb drives, USB stick) or external hard drives from one computer to another, usually instead of transmitting the information over a computer network. The term, a tongue-in-cheek play on Ethernet, refers to the use of someone wearing sneakers as the transport mechanism for the data. You can watch the following video to see an example of Sneakernet. 3.3 What is a firewall?: What is a firewall? | KEATS (LD: only if video is KD-produced, not needed for 3rd party videos) Sneakernet Dr Ievgeniia Kuzminykh Senior Lecturer in Cybersecurity Education View transcript Dr Ievgeniia Kuzminykh | Senior Lecturer in Cybersecurity Education Hi. In this video, we are going to take a look at an attack called ‘Sneakernet’, which is an informal term for the transfer of electronic information by physically moving media such as optical discs, USB flash drives or external hard drives between computers, rather than transmitting it over a computer network. We are going to have a look at an example from Mr Robot. This clip from Mr Robot, season 1, episode 6, shows us an attempt to bypass the potential protections that are in place to protect a precinct. Now, let’s play the clip. [A woman is walking on a parking lot and dropping on the ground several USB flash drives.] Elliot, the hacker, aims to get into the police network infrastructure. He recruited Darlene to pull off a simple, but classic penetration testing technique. Let's pause for a moment and look at this scene. In order to allow Elliot to get access to the IT police infrastructure, she is planting poisoned USB sticks in hopes that someone will plug one in, in front of the | R3: Low | 1.11 | S3: 2
A4: 3 | B4: Week 1 | C4: Medium | D4: CIA Triad | E4: Which property of the CIA triad does a denial-of-service attack primarily target? | F4: Availability; DoS denies access to services | G4: No | H4: Answer: Availability. | I4: 4 | J4: 5 | K4: 4 | L4: 4 | M4: 25.13 | N4: Medium | O4: N | Q4: [Source 1 | Week 1 | Knowledge check PDF | quiz | dist=0.956] ___________ is how individuals and organisation reduce the risk of network attack. a.Network security b.Data security c. Cyber security d.Systems security e.Information security Your answer is incorrect. The correct answer is: Network security ___________ involves the passive capture of a data unit and its subsequent transmission to produce an unauthorised eﬀect. a.Man-in-the-middle attack b.Denial of service attack c. Masquerade d.Replay attack e.Disruption Your answer is incorrect. The correct answer is: Replay attack ____________ is a security mechanism that inserts bits into gaps in a data stream to frustrate traﬃc analysis. a.Access control b.Security recovery c. Notarisation d.Traﬃc padding e. Compression Your answer is incorrect. The correct answer is: Traﬃc padding All the techniques for providing security have two components: a security-related transformation on the information to be sent and some secret information shared by the two principals. Select one: True False The correct answer is 'True'. Which one of the security properties in the CIA triad is the most important? a.Conﬁdentiality b.Availability c. They are equally important d.The importance is situational e.Integrity Your answer is incorrect. The correct answer is: The importance is situational Which service is the one that protects a system to ensure its availability and addresses the security concerns raised by denial- of- service attacks? a.replay b.masquerade c. integrity d.non-repudiation e.availability Your answer is incorrect. The correct answer is: availability The ﬁrst step in the 5Ds of perimeter security is ____________. a.defend b.detect c. delay d.deter e.deny Your answer is incorrect. The correct answer is: deter Listening to network conversation that are not intended for you is called ___________. a.jamming b.sniﬃng c. spooﬁng d.ﬂooding e. hijacking Your answer is incorrect. The correct answer is: sniﬃng A _____________ is any action that compromises the security of information owned by an organisation. a.security monitoring b.security service c. security attack d.security alert e.security mechanism Your answer is incorrect. The correct answer is: security attack ________________ is an attack that pretends to be somebody you are not. a.jamming b.sniﬃng c. ﬂooding d.spooﬁng e.smurﬁng Your answer is incorrect. The correct answer is: spooﬁng  [Source 2 | Week 1 | Network attacks | lecture | dist=1.003] communication between two entities, resembling an aeroplane hijacker taking control of a flight. For instance, a session hijacking attack involves an attacker intercepting packets between two components and taking control of the session between them by inserting their own packet. Poisoning We refer to poisoning as a way to contaminate some source of information that we usually believe is good. Later on in the module, we are going to learn more about ARP poisoning and DNS cache poisoning. Each type of attack can be linked to one of the security principles (see ‘CIA triad’ in lesson ‘How do we define security?’). [Graphic – full-width] Redraw Figure: CIA triad: confidentiality, integrity, availability. Read text below on how different attacks are linked to each assurance. Caption: Sniffing attacks the confidentiality of the communication, since it corresponds to theft or interception of data by capturing network traffic. A potential solution for sniffing is using cryptography to encrypt the communication. Spoofing and poisoning attack the integrity. The goal of a poisoning attack is to change something by corrupting or manipulating information. A spoofing attack also attacks integrity, since it allows the attacker to pretend to be someone else. In order to protect integrity, we can leverage keys to sign what we want to protect. In case of alteration, we would be able to discover that our data were tampered with. A jamming attack compromises the availability of the communication channel, creating noise to make the communication impossible. Policies are a measure to help protect against jamming attacks, restricting what the users can do in the communication channels. Of course, the above solutions are not always feasible and often we need to balance practicality and cost with the importance of the data we want to protect. Off-path vs on-path attackers Finally, let’s look at a useful distinction between two different types of attack: on-path and off-path. On-path means the attacker is operating within the same network. Off-path means they are attacking from outside the network. On-path attacks are much more powerful as it is very difficult to insert false data off-path. There was a lot of terminology introduced in these opening lessons. Take your time to review the definitions as they are used throughout the module. Reference We have used the following sources to compile this lesson. You do not need to read these; they are simply there for your reference and in case you would like to learn more about the information presented in this lesson. [1] J. Postel, “Internet Protocol – DARPA Internet Program Protocol Specification,” Defense Advanced Research Projects Agency, Arlington, Virginia, RFC 791, 1981. [Online]. Available: https://datatracker.ietf.org/doc/html/rfc791 [Source 3 | Week 3 | Knowledge check | quiz | dist=1.15] ‘command & control’) is able to direct the activities of each compromised device (known as a ‘bot’) using network protocols like HTTP. Botnets are used for distributed denial of service (DDoS) attacks and other types of attacks (spam, data theft, etc). [Multiple choice question] Question Question number: 8 Question text: Imagine you are a network administrator. You see a familiar IP address pinging the broadcast address. What could be possibly happening in this case? Settings Number of answers: [One/Multiple] Shuffle answers? [Yes/No] Answers (Please highlight the correct answer) Feedback (Optional feedback for each individual answer) A man-in-the-middle attack. An ARP spoofing attack. A smurfing attack. A DNS poisoning attack. General Feedback A smurf attack is a distributed denial-of-service (DDoS) attack in which large numbers of Internet Control Message Protocol (IMCP) packets with the intended victim's spoofed source IP are broadcast to a computer network using an IP broadcast address. ICMP packets are typically used to PING computers within a LAN; PING is a utility used to test the reachability of a host on a network. [Multiple choice question] Question Question number: 9 Question text: What is a SYN flooding attack? Settings Number of answers: [One/Multiple] Shuffle answers? [Yes/No] Answers (Please highlight the correct answer) Feedback (Optional feedback for each individual answer) A DoS attack that cannot be used jointly with IP spoofing. An attack that requires a modification of the TCP layer (lever 4 OSI) of the server. A buffer overflow attack. A DoS attack that can be used jointly with IP spoofing. General Feedback A SYN flooding attack works by sending a high volume of SYN requests to the targeted server, often with spoofed IP addresses, but not responding to the server with the expected ACK code. For King’s Digital production team LD: Please include choice settings in all storyboards. Delete options in square brackets so that only the desired settings remain. Highlighted options are strongly recommended and, if left untouched, this setting will be applied in the build. [Quiz settings] Grade Grade to pass [None / 1-100] Layout New page [Questions all on one page (recommended) / Questions on individual pages] Question behaviour Shuffle within questions?: [No (recommended) / Yes] How questions behave: Deferred feedback (recommended) / Immediate feedback] Appearance Show blocks during quiz attempts Yes (recommended) Review options LDs: please refer to external guidance for support on Review options. [Additional information: highlighted options in yellow are for LDs to choose, or leave as default. Greyed-out options unavailable to edit] During the attempt Immediately after the attempt Later, while the quiz is still open After quiz is closed The attempt [locked] X [default] X [default] X [locked] Whether correct [locked] X [default] X [default] X [locked] Maximum marks X [default] X [default] X [default] X [locked] Marks [locked] X [default] X [default] X [locked] Specific feedback [locked] X [default] X [default] X [locked] General feedback [locked] X [default] X [default] X [locked] Right answer [locked] X [default] X [default] X [locked] Overall feedback [locked] X [default] X [default] [Source 4 | Week 1 | How do we define security | lecture | dist=1.156] 1.5 How do we define security? As a security expert responsible for security design, it is necessary to understand three things: Who or what is being protected? Who or what is attacking? What are the attacker’s powers? The answers to these questions make up what is called the threat model. Before starting to talk about securing a network, it is necessary to work out what the potential threats are for that specific network. As part of any analysis, we have principals. These principals are actors and participants that have a role in our analysis. Some agents are honest and some are not. As in many examples, let’s consider Alice and Bob. [Graphic – full-width] Figure: A diagram showing Alice and Bob communicating over a network, with a dishonest agent, Mallory, intercepting their communications. Caption: Alice and Bob use the internet to exchange information. Alice and Bob are the honest agents. However, the internet is vast and the communication between Alice and Bob is of some kind of interest for Mallory, who is a dishonest agent. Mallory is exploiting some internet vulnerabilities to get access to the information exchanged by Alice and Bob. How to define security Once we have identified the principals that can affect the security, we need to understand what security means. [Key concept box] Security can be defined as a combination of policy and mechanism. Policy and security properties A security policy is just a statement about what is allowed and not allowed to do in a system or on the ‘object’ being protected. This is defined by specifying security properties that must hold. The most common security properties are confidentiality, integrity and availability, which constitute what is commonly known as the CIA triad. [Card vertical (no image)] Confidentiality Assures that private or confidential information is not disclosed to unauthorised individuals. [Card vertical (no image)] Integrity Assures that information and programs are changed only in a specified and authorised manner. [Card vertical (no image)] Availability Assures that systems work promptly and service is not denied to authorised users. Security mechanisms Once we have the security properties, we need security mechanisms which describe how to implement the security properties. We can think of the mechanisms as tools, methodologies or procedures for security enforcement. For example, let’s say to protect the integrity of the network we have introduced the security mechanisms ‘Only "root" can execute this script’. We can then enforce this property by asking users to input the admin password in addition to checking if the user ID has root privileges. A different example of a property is that voters can only vote once in any given election. This is then implemented in many countries by the mechanism of staining the voters’ fingers with indelible ink to detect if they return back. In other countries the name of the voter is deleted from a database. We can refer to security mechanisms based on their type. The following three are the most important. [Card vertical (no image)] Deter Deterring [Source 5 | Week 5 | Quiz week 1-5 | quiz | dist=1.169] text: Which attack is considered as an active attack? Settings Number of answers: [One/Multiple] Shuffle answers? [Yes/No] Answers (Please highlight the correct answer) Feedback (Optional feedback for each individual answer) Sniffing This is incorrect. Port mirroring This is incorrect. Network tapping This is incorrect. Spoofing This is correct. Eavesdropping This is incorrect. General Feedback Sniffing, network tapping, port mirroring and eavesdropping are passive attacks. Only spoofing is an active attack. [new page] Alice and Bob are CEO and CFO of a cooperation called SecureGalaxia, and you are a network administrator. Alice and Bob used to share a big open office with other colleagues including Charly and David before the Covid –19 pandemic. The simplified topology of their local area network is shown below, with the IP address of their machines listed. [Graphic – full-width] Figure: View the description below. Caption: [View description] View description In the local area network, four machines are connected to one central server. Their IP addresses are listed as below. Bob’s IP address: 10.0.0.2 David’s IP address: 10.0.0.5 Charly’s IP address: 10.0.0.4 Alice’s IP address: 10.0.0.3 One day you wanted to install an update on Bob’s machine. When you checked the ARP table on his machine, you saw the output as below: (10.0.0.2) at 1e:25:d2:11:8c:a2 [either] on h1-eth0 (10.0.0.4) at cc:cc:cc:cc:cc:cc [either] PERM on h1-eth0 (10.0.0.3) at cc:cc:cc:cc:cc:cc [either] PERM on h1-eth0 You thought this is strange, knowing that the MAC address cc:cc:cc:cc:cc:cc is Charly’s machine. However, Bob never had any problems of communicating with Alice on the network. [Essay question] Question Question number: Question text: What do you think is happening? In your analysis, include the following: What type of attack is this? What does the ARP table on Alice’s machine look like when she checks? Describe the attack in full detail in the context of the given scenario. What can Alice and Bob do to mitigate such attack(s) in the future? General feedback (relevant for the question as a whole) What type of attack is this? What does the ARP table at Alice’s machine look like when she checks? To answer this question, you are advised to revisit the week 3 lessons on network attacks, ARP spoofing, ARP poisoning and ARP cache poisoning. This is an ARP spoofing/ARP poisoning/ARP cache poisoning/man-in-the-middle attack. The ARP table shown on Alice’s machine looks like this: (10.0.0.3) at xx:xx:xx:xx:xx:xx [ether] on eth0, where xx:xx:xx:xx:xx:xx can be any valid Ethernet MAC address. x should be between 0 to f. eth0 can be any other port number except localhost. (10.0.0.4) at cc:cc:cc:cc:cc:cc [ether] PERM on h1-eth0. The fields from PERM are for examples only. (10.0.0.2) at cc:cc:cc:cc:cc:cc [ether] PERM on h1-etho. The fields from PERM are for examples only. Describe the attack in full detail with the given scenario. Your answer should describe how Charly mounts the attack, spoofs the ARP response and poisons the ARP cache, for both Alice and Bob, and becomes the man-in-the-middle of the communication between Alice and Bob. You may use diagram(s) to illustrate the | R4: Medium | 1.087 | S4: 3
